<?xml version="1.0" encoding="utf-8"?>
<!-- This URDF was automatically created by SolidWorks to URDF Exporter! Originally created by Stephen Brawner (brawner@gmail.com) 
     Commit Version: 1.6.0-4-g7f85cfe  Build Version: 1.6.7995.38578
     For more information, please see http://wiki.ros.org/sw_urdf_exporter -->
<robot
  name="arm_BRTIRUS0805A_SLDASM">
  <link
    name="base_link">
    <inertial>
      <origin
        xyz="-0.079879 0.065571 0.30338"
        rpy="0 0 0" />
      <mass
        value="35.943" />
      <inertia
        ixx="4.8963"
        ixy="0.22178"
        ixz="1.0455"
        iyy="4.9892"
        iyz="-0.99002"
        izz="0.75129" />
    </inertial>
    <visual>
      <origin
        xyz="0 0 0"
        rpy="0 0 0" />
      <geometry>
        <mesh
          filename="package://cpp06_urdf/meshes/base_link.STL" />
      </geometry>
      <material
        name="">
        <color
          rgba="0.79216 0.81961 0.93333 1" />
      </material>
    </visual>
    <collision>
      <origin
        xyz="0 0 0"
        rpy="0 0 0" />
      <geometry>
        <mesh
          filename="package://cpp06_urdf/meshes/base_link.STL" />
      </geometry>
    </collision>
  </link>
  <link
    name="Link1">
    <inertial>
      <origin
        xyz="-0.079879 0.065571 0.30338"
        rpy="0 0 0" />
      <mass
        value="35.943" />
      <inertia
        ixx="4.8963"
        ixy="0.22178"
        ixz="1.0455"
        iyy="4.9892"
        iyz="-0.99002"
        izz="0.75129" />
    </inertial>
    <visual>
      <origin
        xyz="0 0 0"
        rpy="0 0 0" />
      <geometry>
        <mesh
          filename="package://cpp06_urdf/meshes/Link1.STL" />
      </geometry>
      <material
        name="">
        <color
          rgba="1 1 1 1" />
      </material>
    </visual>
    <collision>
      <origin
        xyz="0 0 0"
        rpy="0 0 0" />
      <geometry>
        <mesh
          filename="package://cpp06_urdf/meshes/Link1.STL" />
      </geometry>
    </collision>
  </link>
  <joint
    name="joint1"
    type="continuous">
    <origin
      xyz="0 0 0"
      rpy="0 0 0" />
    <parent
      link="base_link" />
    <child
      link="Link1" />
    <axis
      xyz="0 0 1" />
    <limit
      lower="-3.14"
      upper="3.14"
      effort="100"
      velocity="3.14" />
  </joint>
  <link
    name="Link2">
    <inertial>
      <origin
        xyz="0.047056 0.084107 0.12388"
        rpy="0 0 0" />
      <mass
        value="35.943" />
      <inertia
        ixx="4.8963"
        ixy="0.22178"
        ixz="1.0455"
        iyy="4.9892"
        iyz="-0.99002"
        izz="0.75129" />
    </inertial>
    <visual>
      <origin
        xyz="0 0 0"
        rpy="0 0 0" />
      <geometry>
        <mesh
          filename="package://cpp06_urdf/meshes/Link2.STL" />
      </geometry>
      <material
        name="">
        <color
          rgba="0.79216 0.81961 0.93333 1" />
      </material>
    </visual>
    <collision>
      <origin
        xyz="0 0 0"
        rpy="0 0 0" />
      <geometry>
        <mesh
          filename="package://cpp06_urdf/meshes/Link2.STL" />
      </geometry>
    </collision>
  </link>
  <joint
    name="joint2"
    type="continuous">
    <origin
      xyz="-0.12694 -0.018536 0.1795"
      rpy="0 0 0" />
    <parent
      link="Link1" />
    <child
      link="Link2" />
    <axis
      xyz="0.75035 0.66104 0" />
    <limit
      lower="-3.14"
      upper="3.14"
      effort="100"
      velocity="3.14" />
  </joint>
  <link
    name="Link3">
    <inertial>
      <origin
        xyz="0.15627 -0.041376 -0.22886"
        rpy="0 0 0" />
      <mass
        value="35.943" />
      <inertia
        ixx="4.8963"
        ixy="0.22178"
        ixz="1.0455"
        iyy="4.9892"
        iyz="-0.99002"
        izz="0.75129" />
    </inertial>
    <visual>
      <origin
        xyz="0 0 0"
        rpy="0 0 0" />
      <geometry>
        <mesh
          filename="package://cpp06_urdf/meshes/Link3.STL" />
      </geometry>
      <material
        name="">
        <color
          rgba="0.79216 0.81961 0.93333 1" />
      </material>
    </visual>
    <collision>
      <origin
        xyz="0 0 0"
        rpy="0 0 0" />
      <geometry>
        <mesh
          filename="package://cpp06_urdf/meshes/Link3.STL" />
      </geometry>
    </collision>
  </link>
  <joint
    name="joint3"
    type="continuous">
    <origin
      xyz="-0.10921 0.12548 0.35274"
      rpy="0 0 0" />
    <parent
      link="Link2" />
    <child
      link="Link3" />
    <axis
      xyz="0.75035 0.66104 0" />
    <limit
      lower="-3.14"
      upper="3.14"
      effort="100"
      velocity="3.14" />
  </joint>
  <link
    name="Link4">
    <inertial>
      <origin
        xyz="0.033038 -0.062024 -0.36559"
        rpy="0 0 0" />
      <mass
        value="35.943" />
      <inertia
        ixx="4.8963"
        ixy="0.22178"
        ixz="1.0455"
        iyy="4.9892"
        iyz="-0.99002"
        izz="0.75129" />
    </inertial>
    <visual>
      <origin
        xyz="0 0 0"
        rpy="0 0 0" />
      <geometry>
        <mesh
          filename="package://cpp06_urdf/meshes/Link4.STL" />
      </geometry>
      <material
        name="">
        <color
          rgba="1 1 1 1" />
      </material>
    </visual>
    <collision>
      <origin
        xyz="0 0 0"
        rpy="0 0 0" />
      <geometry>
        <mesh
          filename="package://cpp06_urdf/meshes/Link4.STL" />
      </geometry>
    </collision>
  </link>
  <joint
    name="joint4"
    type="continuous">
    <origin
      xyz="0.12323 0.020648 0.13672"
      rpy="0 0 0" />
    <parent
      link="Link3" />
    <child
      link="Link4" />
    <axis
      xyz="-0.27889 0.31657 0.90664" />
    <limit
      lower="-3.14"
      upper="3.14"
      effort="100"
      velocity="3.14" />
  </joint>
  <link
    name="Link5">
    <inertial>
      <origin
        xyz="0.098965 -0.11601 -0.65537"
        rpy="0 0 0" />
      <mass
        value="35.943" />
      <inertia
        ixx="4.8963"
        ixy="0.22178"
        ixz="1.0455"
        iyy="4.9892"
        iyz="-0.99002"
        izz="0.75129" />
    </inertial>
    <visual>
      <origin
        xyz="0 0 0"
        rpy="0 0 0" />
      <geometry>
        <mesh
          filename="package://cpp06_urdf/meshes/Link5.STL" />
      </geometry>
      <material
        name="">
        <color
          rgba="1 1 1 1" />
      </material>
    </visual>
    <collision>
      <origin
        xyz="0 0 0"
        rpy="0 0 0" />
      <geometry>
        <mesh
          filename="package://cpp06_urdf/meshes/Link5.STL" />
      </geometry>
    </collision>
  </link>
  <joint
    name="joint5"
    type="continuous">
    <origin
      xyz="-0.065927 0.053985 0.28978"
      rpy="0 0 0" />
    <parent
      link="Link4" />
    <child
      link="Link5" />
    <axis
      xyz="0.35431 -0.84358 0.40354" />
    <limit
      lower="-3.14"
      upper="3.14"
      effort="100"
      velocity="3.14" />
  </joint>
  <link
    name="Link6">
    <inertial>
      <origin
        xyz="0.0033322 -0.00086479 -0.0047903"
        rpy="0 0 0" />
      <mass
        value="0.17509" />
      <inertia
        ixx="0.00013622"
        ixy="-7.96E-06"
        ixz="-4.6542E-05"
        iyy="0.00010784"
        iyz="1.2013E-05"
        izz="0.00016934" />
    </inertial>
    <visual>
      <origin
        xyz="0 0 0"
        rpy="0 0 0" />
      <geometry>
        <mesh
          filename="package://cpp06_urdf/meshes/Link6.STL" />
      </geometry>
      <material
        name="">
        <color
          rgba="1 0.16863 0.16863 1" />
      </material>
    </visual>
    <collision>
      <origin
        xyz="0 0 0"
        rpy="0 0 0" />
      <geometry>
        <mesh
          filename="package://cpp06_urdf/meshes/Link6.STL" />
      </geometry>
    </collision>
  </link>
  <joint
    name="joint6"
    type="continuous">
    <origin
      xyz="-0.084674 0.058136 0.076471"
      rpy="0 0 0" />
    <parent
      link="Link5" />
    <child
      link="Link6" />
    <axis
      xyz="-0.56953 0.1476 0.80861" />
    <limit
      lower="-3.14"
      upper="3.14"
      effort="100"
      velocity="3.14" />
  </joint>
</robot>